<!DOCTYPE html>
<html lang="en">

<head>
    <meta charset="UTF-8">
    <meta http-equiv="X-UA-Compatible" content="IE=edge">
    <meta name="viewport" content="width=device-width, initial-scale=1.0">
    <title>Document</title>
</head>

<body>
    <script>
        // promise方法，因为第一个.then中throw了error，导致直接进入catch阶段，跳过了下面的console，catch正确执行完之后进入下面的.then
        // new Promise((resolve, reject) => {
        //         console.log('初始化');

        //         resolve();
        //     })
        //     .then(() => {
        //         throw new Error('发生错误！');

        //         console.log('执行[这个]');
        //     })
        //     .catch(() => {
        //         console.log('执行[那个]');
        //     })
        //     .then(() => {
        //         console.log('无论如何，都会执行这个');
        //     })

        // 组合函数形式，函数执行时序
        const wait = ms => new Promise(resolve => setTimeout(resolve, ms));

        wait().then(() => console.log(4));
        Promise.resolve().then(() => console.log(2)).then(() => console.log(3));
        console.log(1); // 1, 2, 3, 4
    </script>
</body>

</html>